2019-12-17 19:14:36,924-DEBUG-my_log.py-python11-日志信息:这是一个。。。
2020-02-11 11:02:50,117-ERROR-my_log.py-python11-日志信息:请求报错了：HTTPConnectionPool(host='119.23.241.154', port=8080): Max retries exceeded with url: /futureloan/mvc/api/member/login?mobilephone=15096099000&pwd=123456 (Caused by NewConnectionError('<urllib3.connection.HTTPConnection object at 0x0000022436C885C0>: Failed to establish a new connection: [WinError 10060] 由于连接方在一段时间后没有正确答复或连接的主机没有反应，连接尝试失败。'))
2020-02-11 11:03:11,158-ERROR-my_log.py-python11-日志信息:请求报错了：HTTPConnectionPool(host='119.23.241.154', port=8080): Max retries exceeded with url: /futureloan/mvc/api/member/login (Caused by NewConnectionError('<urllib3.connection.HTTPConnection object at 0x0000022436A8A2B0>: Failed to establish a new connection: [WinError 10060] 由于连接方在一段时间后没有正确答复或连接的主机没有反应，连接尝试失败。'))
2020-02-11 11:03:32,175-ERROR-my_log.py-python11-日志信息:请求报错了：HTTPConnectionPool(host='119.23.241.154', port=8080): Max retries exceeded with url: /futureloan/mvc/api/member/login?mobilephone=15096099000&pwd=123456 (Caused by NewConnectionError('<urllib3.connection.HTTPConnection object at 0x0000022436C2AA20>: Failed to establish a new connection: [WinError 10060] 由于连接方在一段时间后没有正确答复或连接的主机没有反应，连接尝试失败。'))
2020-02-11 11:03:53,184-ERROR-my_log.py-python11-日志信息:请求报错了：HTTPConnectionPool(host='119.23.241.154', port=8080): Max retries exceeded with url: /futureloan/mvc/api/member/login (Caused by NewConnectionError('<urllib3.connection.HTTPConnection object at 0x0000022436A5ABE0>: Failed to establish a new connection: [WinError 10060] 由于连接方在一段时间后没有正确答复或连接的主机没有反应，连接尝试失败。'))
2020-02-11 11:04:14,193-ERROR-my_log.py-python11-日志信息:请求报错了：HTTPConnectionPool(host='119.23.241.154', port=8080): Max retries exceeded with url: /futureloan/mvc/api/member/login?mobilephone=15096099000&pwd=123456 (Caused by NewConnectionError('<urllib3.connection.HTTPConnection object at 0x0000022436A4E828>: Failed to establish a new connection: [WinError 10060] 由于连接方在一段时间后没有正确答复或连接的主机没有反应，连接尝试失败。'))
2020-02-11 11:05:39,846-ERROR-my_log.py-python11-日志信息:请求报错了：HTTPConnectionPool(host='119.23.241.154', port=8080): Max retries exceeded with url: /futureloan/mvc/api/member/login?mobilephone=15096099000&pwd=123456 (Caused by NewConnectionError('<urllib3.connection.HTTPConnection object at 0x00000224368CC748>: Failed to establish a new connection: [WinError 10060] 由于连接方在一段时间后没有正确答复或连接的主机没有反应，连接尝试失败。'))
